Workbook

Sheet Dashboard
A1: Dashboard
A3: Stage 2: Rubrics Average Score based on Languages
A5: Linguistic Quality Ratings by Language
A6: Language | B6: Accuracy / Completeness | C6: Translation Accuracy | D6: Grammar and Fluency | E6: Language Purity
A7: Telugu | B7: =average('Stage 2_Telugu'!E3:E246) -> 3.1 | C7: =average('Stage 2_Telugu'!I3:I246) -> 2.8 | D7: =average('Stage 2_Telugu'!J3:J246) -> 3.2333333 | E7: =average('Stage 2_Telugu'!K3:K246) -> 3.0666667
A8: Assamese | B8: =average('Stage 2_Assamese'!E3:E2476) -> 3.6333333 | C8: =average('Stage 2_Assamese'!I4:I247) -> 3.9666667 | D8: =average('Stage 2_Assamese'!J4:J247) -> 4 | E8: =average('Stage 2_Assamese'!K4:K247) -> 3.4
A9: Bengali | B9: =average('Stage 2_Bengali'!E4:E2477) -> 3.3666667 | C9: =average('Stage 2_Bengali'!I5:I248) -> 4 | D9: =average('Stage 2_Bengali'!J5:J248) -> 4 | E9: =average('Stage 2_Bengali'!K5:K248) -> 2.9333333
A10: Gujarati | B10: =average('Stage 2_Gujarati'!E5:E2478) -> 3.4 | C10: =average('Stage 2_Gujarati'!I6:I34) -> 4 | D10: =average('Stage 2_Gujarati'!J6:J34) -> 4 | E10: =average('Stage 2_Gujarati'!K6:K34) -> 3.2758621
A11: Kannada | B11: =average('Stage 2_Kannada'!E6:E2479) -> 3.5172414 | C11: =average('Stage 2_Kannada'!I7:I250) -> 3.8928571 | D11: =average('Stage 2_Kannada'!J7:J250) -> 3.9285714 | E11: =average('Stage 2_Kannada'!K7:K250) -> 3.3928571
A12: Malayalam | B12: =average('Stage 2_Malayalam'!E7:E2480) -> 3.6071429 | C12: =average('Stage 2_Malayalam'!I8:I251) -> 3.2962963 | D12: =average('Stage 2_Malayalam'!J8:J251) -> 3.5925926 | E12: =average('Stage 2_Malayalam'!K8:K251) -> 3.8518519
A13: Marathi | B13: =average('Stage 2_Marathi'!E8:E2481) -> 3.1851852 | C13: =average('Stage 2_Marathi'!I9:I252) -> 3.9615385 | D13: =average('Stage 2_Marathi'!J9:J252) -> 3.6923077 | E13: =average('Stage 2_Marathi'!K9:K252) -> 3.6153846
A14: Tamil | B14: =average('Stage 2_Tamil'!E9:E2482) -> 3.5769231 | C14: =average('Stage 2_Tamil'!I10:I253) -> 4 | D14: =average('Stage 2_Tamil'!J10:J253) -> 4 | E14: =average('Stage 2_Tamil'!K10:K253) -> 4
A17: Functional & Factual Grounding Pass Rates by Language
A18: Language | B18: Actionability | C18: Conversation Closure | D18: Source Data Comprehensiveness | E18: No Fabrication | F18: Citation Accuracy
A19: Telugu | B19: 1 | C19: 1 | D19: 1 | E19: 0.91666667 | F19: 0.875
A20: Assamese | B20: 0.86666667 | C20: 1 | D20: 0.83333333 | E20: 0.86206897 | F20: 0.55172414
A21: Bengali | B21: 1 | C21: 0.96666667 | D21: 1 | E21: 0.91666667 | F21: 0.95833333
A22: Gujarati | B22: 0.93103448 | C22: 1 | D22: 0.72413793 | E22: 0.82608696 | F22: 0.7826087
A23: Kannada | B23: 0.96428571 | C23: 1 | D23: 0.82142857 | E23: 0.90909091 | F23: 0.81818182
A24: Malayalam | B24: 0.92592593 | C24: 1 | D24: 0.88888889 | E24: 0.86956522 | F24: 0.86956522
A25: Marathi | B25: 1 | C25: 0.96153846 | D25: 0.73076923 | E25: 0.95 | F25: 0.8
A26: Tamil | B26: 1 | C26: 1 | D26: 0.64 | E26: 0.78947368 | F26: 0.68421053
A29: Total | B29: 240 | C29: 🟢 Completed | D29: 240 | E29: 🟡 In Progress | F29: 0 | G29: 🔴 Not Started | H29: 0 | I29: Completion % | J29: 1
A31: Language | B31: Total | C31: Completed | D31: In Progress | E31: Not Started | F31: Completion Percentage
A32: Stage 2_Telugu | B32: 30 | C32: 30 | D32: 0 | E32: 0 | F32: 1
A33: Stage 2_Assamese | B33: 30 | C33: 30 | D33: 0 | E33: 0 | F33: 1
A34: Stage 2_Bengali | B34: 30 | C34: 30 | D34: 0 | E34: 0 | F34: 1
A35: Stage 2_Gujarathi | B35: 30 | C35: 30 | D35: 0 | E35: 0 | F35: 1
A36: Stage 2_Kannada | B36: 30 | C36: 30 | D36: 0 | E36: 0 | F36: 1
A37: Stage 2_Malayalam | B37: 30 | C37: 30 | D37: 0 | E37: 0 | F37: 1
A38: Stage 2_Marathi | B38: 30 | C38: 30 | D38: 0 | E38: 0 | F38: 1
A39: Stage 2_Tamil | B39: 30 | C39: 30 | D39: 0 | E39: 0 | F39: 1
A40: TOTAL | B40: 240 | C40: 240 | D40: 0 | E40: 0 | F40: 1

Sheet Stage 2_Telugu
C1: Whenever you select a score, its definition will appear here. Please review it before submitting your evaluation. | E1: Select a score to see the scoring description.
A3: EVALUATION CATEGORY | E3: RESPONSE USEFULNESS | I3: LINGUISTIC QUALITY | L3: The response should contain the exact attribute values from the source. This verifies that the model has not fabricated, modified, or omitted any source information. | M3: FACTUAL GROUNDING | O3: Please add any required corrections and a detailed overall remarks based on scores provided. | P3: Status | Q3: QC Feedback | T3: Evaluator response to reviewer Feedback
A4: ID | B4: question_id | C4: Prompt | D4: Response | E4: Accuracy / Completeness (1-4) | F4: Actionability (0/1) | G4: Conversation Closure (0/1) | H4: Source Data Comprehensiveness (0/1) | I4: Translation Accuracy (1-4) | J4: Grammar and Fluency (1-4) | K4: Language Purity (1-4) | L4: Tool Source data | M4: No Fabrication (0/1) Note: Verify response with tool source data | N4: Citation Accuracy (0/1) Note: Verify response with tool source data | Q4: Score | R4: Status | S4: Detailed Remarks
A5: 1 | B5: 1-1 | C5: ముంబై మాండి లో ఈ రోజు ఆల్ మిర్చి ధరలు ఏమిటి? | D5: ముంబై మాండిలో ఎర్ర మిర్చికి సంబంధించిన ధరల సమాచారం ప్రస్తుతం అందుబాటులో లేదు. **మూలం: మండి ధరలు** మీకు వేరే పంట ధరల గురించి లేదా ఇతర ప్రాంతాల ధరల గురించి తెలియాలా? | E5: 4 | F5: 1 | G5: 1 | H5: 1 | I5: 2 | J5: 3 | K5: 3 | L5: [tool:get_mandi_prices] **Mandi Price Discovery** [Today's Date: Monday, 25 May 2026] No mandi price data found for the requested location and commodity. [tool:search_commodity] ### Commodity matches for `all mirchi` | Commodity | Matched Term (Score) | Code | |---|---|---| | **Chili Red** | lal mirchi (95%) | `26` | | **Round Chilli** | gol mirchi (89%) | `520` | | **Black pepper** | kali mirch (84%) | `34` | | **Chilly Capsicum** | mirchi (80%) | `74` | | **Pepper ungarbled** | mirchi (80%) | `94` | [tool:forward_geocode] Mumbai, Mumbai Suburban, Maharashtra, India (Latitude: 19.055, Longitude: 72.869) | M5: 1 | N5: 0 | O5: In promt it said all prices of mirchi in Mumbai mandi , but in the response it said red mirchi prices are not available for Mumbai location instead of giving information about all kind of mirchi | P5: Completed | Q5: 2 | R5: Needs Re-evaluation | S5: Stage 2 correctly flipped Citation Accuracy to 0 due to untranslated numbers. | T5: updated
A6: 2 | B6: 2-1 | C6: పార్భణి ప్రాంతంలో పంట బీమా పథకానికి అవసరమైన పత్రాలు ఏమిటి? | D6: పిఎం ఫసల్ బీమా యోజన (PMFBY) కింద పంట బీమా కోసం ఈ క్రింది పత్రాలు అవసరం: * ఆధార్ కార్డు * భూమి రికార్డులు లేదా లీజు ఒప్పంద పత్రం (అద్దెకు తీసుకున్న రైతులకు) * బ్యాంకు ఖాతా వివరాలు * పట్వారీ లేదా వ్యవసాయ అధికారి నుండి పొందిన పంట సాగు ధృవీకరణ పత్రం * పంట నష్టం సంభవించినప్పుడు, పంట ఫోటోలు (క్లెయిమ్ కోసం) **మూలం: ప్రభుత్వ పథక సమాచారం** మీరు ఇప్పటికే ఈ పథకానికి దరఖాస్తు చేసుకున్నారా లేదా కొత్తగా దరఖాస్తు చేయాలనుకుంటున్నారా? | E6: 4 | F6: 1 | G6: 1 | H6: 1 | I6: 4 | J6: 4 | K6: 4 | L6: [tool:get_scheme_info] **Source:** PM Fasal Bima Yojana (PMFBY) ## Introduction Pradhan Mantri Fasal Bima Yojana (PMFBY) was launched in January 2016 as a comprehensive crop insurance scheme replacing the earlier National Agricultural Insurance Scheme (NAIS). It provides financial support to farmers suffering crop loss or damage due to unforeseen events like natural calamities, pests, and diseases. ## Benefits Coverage for crop losses due to non-preventable natural risks, prevented sowing, post-harvest losses, and localized calamities. Premium rates are very low: 2% for Kharif crops, 1.5% for Rabi crops, 5% for commercial/horticultural crops. Government pays the balance premium. Sum insured based on Scale of Finance declared by the state. Claims settled within 2 months of harvest. ## Eligibility All farmers including sharecroppers and tenant farmers growing notified crops in notified areas are eligible. Both loanee farmers (mandatory coverage for those with crop loans from banks) and non-loanee farmers (voluntary) can enrol. Aadhaar is mandatory for registration. ## How to Apply Loanee farmers are enrolled automatically by their bank at time of crop loan. Non-loanee farmers can apply through: (1) Banks (nationalised, cooperative, Regional Rural Banks), (2) Common Service Centres (CSC), (3) Insurance company agents, (4) Pradhan Mantri Fasal Bima Yojana portal (pmfby.gov.in). Applications must be submitted before the cutoff date for each season. ## Documents Required Aadhaar card, land records or lease agreement (for tenant farmers), bank account details, crop sowing certificate from Patwari/Agriculture Officer, photograph of standing crop before loss (for post-harvest claims). | M6: 1 | N6: 1 | P6: Completed | Q6: 3 | R6: Accept with Minor Corrections | S6: The overall evaluation is correct and the core findings are valid. Minor 1-point score variances exist between stages, primarily in Accuracy/Completeness. These minor corrections do not impact the overall validity and can be accepted with minor updates. | T6: updated
A7: 3 | B7: 3-1 | C7: సంగ్లీ జిల్లాలో మక్కా పంట కోతకు వాతావరణం అనుకూలంగా ఉందా? | D7: సంగ్లీ జిల్లాలో ప్రస్తుతం మరియు రాబోయే రోజుల్లో తేలికపాటి వర్షాలు మరియు పిడుగులు పడే అవకాశం ఉంది, కాబట్టి మక్కా పంట కోతకు వాతావరణం అంత అనుకూలంగా లేదు. ముఖ్యంగా ఈ రోజు మరియు రేపు వర్ష సూచన ఉన్నందున, కోత పనులను వాయిదా వేయడం మంచిది. మే ౨౬నాడు ఆకాశం పాక్షికంగా మేఘావృతమై ఉంటుంది, కాబట్టి అప్పుడు వాతావరణాన్ని బట్టి నిర్ణయం తీసుకోండి. **మూలం: వాతావరణ సూచన (IMD)** మీకు మక్కా పంట నిల్వ పద్ధతుల గురించి సమాచారం కావాలా? | E7: 4 | F7: 1 | G7: 1 | H7: 1 | I7: 4 | J7: 2 | K7: 2 | L7: [tool:weather_forecast] **Weather Forecast Data** [Today's Date: Monday, 25 May 2026] Responses: Catalog: Weather Catalog for Weather-Forecast-Mausamgram Providers: Provider: Mausamgram Weather Forecast Categories: - Weather Forecast Fulfillments: Fulfillment ID: f1 Stops: - Lat: 16.85, Lon: 74.595 Items: **Item:** Weather Report for Lat: 16.85, Lon: 74.595 Short: Mausamgram Forecast Tags: Today: Location: Lat: 16.85, Lon: 74.595 Date: 2026-05-24 Rainfall: 8.13 mm Min Temp: 24.24 °C Max Temp: 33.5 °C Min Humidity: 50.79 % Max Humidity: 80.42 % Wind Speed: 4.86 m/s Wind Direction: Westerly Weather Condition: Generally Cloudy Sky with possibility of Light Rainfall or Thunderstorm Day_2: Location: Lat: 16.85, Lon: 74.595 Date: 2026-05-25 Rainfall: 3.8 mm Min Temp: 25.5 °C Max Temp: 35.04 °C Min Humidity: 40.37 % Max Humidity: 83.95 % Wind Speed: 4.5 m/s Wind Direction: Westerly Weather Condition: Generally Cloudy Sky with possibility of Light Rainfall or Thunderstorm Day_3: Location: Lat: 16.85, Lon: 74.595 Date: 2026-05-26 Rainfall: 0.77 mm Min Temp: 25.1 °C Max Temp: 34.6 °C Min Humidity: 41.66 % Max Humidity: 84.24 % Wind Speed: 4.05 m/s Wind Direction: Westerly Weather Condition: Partly Cloudy Sky Day_4: Location: Lat: 16.85, Lon: 74.595 Date: 2026-05-27 Rainfall: 3.65 mm Min Temp: 25.5 °C Max Temp: 35.3 °C Min Humidity: 40.57 % Max Humidity: 83.96 % Wind Speed: 4.16 m/s Wind Direction: Westerly Weather Condition: Partly Cloudy Sky with possibility of Light Rainfall or Thunderstorm Day_5: Location: Lat: 16.85, Lon: 74.595 Date: 2026-05-28 Rainfall: 0.12 mm Min Temp: 24.8 °C Max Temp: 35.4 °C Min Humidity: 39.4 % Max Humidity: 82.71 % Wind Speed: 4.83 m/s Wind Direction: Westerly Weather Condition: Mainly Clear Sky [tool:forward_geocode] Sangli, Miraj, Maharashtra, India (Latitude: 16.85, Longitude: 74.595) | M7: 1 | N7: 1 | O7: In response there is word called "may nadu" which looks like not translated well | P7: Completed | Q7: 2 | R7: Needs Re-evaluation | S7: In QID 3-1, concerning maize harvest weather in Sangli, the response contains an untranslated term ('may nadu') and raw numerical values. Stage 2 flipped it to 0 due to language purity and translation flaws. This unaddressed scoring flip requires a Score of 2 (Needs Re-evaluation). Re-evaluate Language Purity, Grammar & Fluency, and Citation Accuracy. | T7: updated
A8: 4 | B8: 4-1 | C8: వర్ధా జిల్లాలో డ్రిప్ ఇరిగేషన్ పథకానికి ఎలా దరఖాస్తు చేయాలి? | D8: డ్రిప్ ఇరిగేషన్ (బిందు సేద్యం) కోసం 'ప్రతి చుక్క ఎక్కువ పంట' (PDMC) పథకం కింద మీరు దరఖాస్తు చేసుకోవచ్చు. దీనికి దరఖాస్తు చేసే విధానం ఇక్కడ ఉంది: **దరఖాస్తు విధానం:** * జిల్లా వ్యవసాయ లేదా ఉద్యానవన శాఖ కార్యాలయం ద్వారా దరఖాస్తు చేసుకోవచ్చు. * రాష్ట్ర ప్రభుత్వ పి.ఎం.కే.ఎస్.వై-పి.డి.ఎం.సి (PMKSY-PDMC) పోర్టల్ ద్వారా ఆన్‌లైన్‌లో దరఖాస్తు చేయవచ్చు. * ప్రభుత్వ గుర్తింపు పొందిన డ్రిప్/స్ప్రింక్లర్ పరికరాల తయారీదారులు లేదా డీలర్ల ద్వారా కూడా దరఖాస్తు చేసుకోవచ్చు. **అవసరమైన పత్రాలు:** * భూమి రికార్డులు (ఖతానంబర్, విస్తీర్ణం). * ఆధార్ కార్డు. * బ్యాంకు ఖాతా వివరాలు. * గుర్తింపు పొందిన వెండర్ నుండి పొందిన కొటేషన్. * నీటి వనరుల లభ్యతకు సంబంధించిన ఆధారాలు. * పొలం యొక్క జియో-ట్యాగ్డ్ ఫోటో. **మూలం: ప్రభుత్వ పథక సమాచారం** మీకు ఈ పథకానికి సంబంధించి అర్హత వివరాలు లేదా సబ్సిడీ మొత్తాల గురించి మరింత సమాచారం కావాలా? | E8: 4 | F8: 1 | G8: 1 | H8: 1 | I8: 4 | J8: 4 | K8: 4 | L8: [tool:get_scheme_info] **Source:** Per Drop More Crop (PDMC) ## Introduction Per Drop More Crop (PDMC) is a component of PM Krishi Sinchayee Yojana (PMKSY) focused exclusively on micro-irrigation — drip and sprinkler systems — to enhance water use efficiency at the farm level. The scheme promotes efficient on-farm water management practices and reduces water wastage while improving crop productivity. ## Benefits Subsidy on drip irrigation systems: 55% for small/marginal farmers (land ≤ 2 ha), 45% for other farmers. Subsidy on sprinkler systems: 55% for small/marginal, 45% for others. Water savings of 40-50% compared to flood irrigation. Yield improvement of 20-50% depending on crop. Also covers secondary storage structures, water-carrying pipes, and fertigation equipment. ## Eligibility All farmers with a minimum of 0.5 acre of agricultural land. Farmers with access to a reliable water source (borewell, canal, river, tank). One-time benefit per farmer per land parcel (subsidy not available if availed within last 7 years). SC/ST and women farmers may get additional state-level benefits. ## How to Apply Apply through: (1) District Agriculture/Horticulture Office, (2) State government PMKSY-PDMC portal, (3) Registered drip/sprinkler equipment manufacturers/dealers. Select empanelled vendor, get installation quote. Submit application with documents. After approval, purchase and install system. Subsidy released after field verification. ## Documents Required Land records (Khasra number, area), Aadhaar card, bank account details, quotation from empanelled/registered vendor, water source availability proof (borewell registration / water permission), geo-tagged photograph of field, caste certificate (for SC/ST farmers). | M8: 1 | N8: 1 | P8: Completed | Q8: 3 | R8: Accept with Minor Corrections | S8: The overall evaluation is correct and the core findings are valid. Minor 1-point score variances exist between stages, primarily in Accuracy/Completeness. These minor corrections do not impact the overall validity and can be accepted with minor updates. | T8: updated
A9: 5 | B9: 5-1 | C9: బుల్ధానా ప్రాంతంలో కాలీఫ్లవర్‌తో ఏ మధ్యపంటలు వేయాలి? | D9: క్షమించండి, బుల్ధానా ప్రాంతంలో కాలీఫ్లవర్‌తో కలిపి వేయవలసిన నిర్దిష్ట మధ్యపంటల (intercrops) గురించి నా వద్ద ఉన్న అధికారిక డేటాలో సమాచారం అందుబాటులో లేదు. మీకు సహాయపడటానికి, మీ పొలంలోని మట్టి ఆరోగ్యం మరియు ప్రస్తుత పరిస్థితుల ఆధారంగా సరైన పంటల ఎంపిక కోసం మీ స్థానిక వ్యవసాయ అధికారిని లేదా కృషి విజ్ఞాన కేంద్రం (కె.వి.కె) ను సంప్రదించవలసిందిగా సూచిస్తున్నాను. మీకు మరేదైనా పంట సలహాలు లేదా ప్రభుత్వ పథకాల గురించి సమాచారం కావాలా? | E9: 1 | F9: 1 | G9: 1 | H9: 1 | I9: 1 | J9: 3 | K9: 2 | L9: [tool:search_documents] > Search Results for `intercropping crops with cauliflower in Buldhana Maharashtra` **ICAR Kharif Agro-Advisories for Farmers** ``` FRUIT CROPS Pomegranate [अनार] The preferred variety is Bhagwa, planted at a spacing [अंतर] of 3.2 x 2.6 meters with a planting density of 1200 plants per hectare between June to September. Propagation [प्रजनन] is done through air layering [गुट्टी कलम] and tissue culture [ऊतक संवर्धन], with cuttings [कटिंग] treated using 5000 ppm IBA. Intercropping [अंतरफसल] with cowpea [लोबिया], cucumber [खीरा], cabbage [पत्ता गोभी], onion [प्याज], and pea [मटर] is practiced during the first 5-6 years. Fertilizer [उर्वरक] dose is 197:99:99 NPK kg/ha. Borax [बोरैक्स] is applied at 1 g/L of water. Drip irrigation [ड्रिप सिंचाई] is scheduled at 11 L/day during rainy season, 12 L/day in winter, and 22 L/day in summer. Herbicides [शाकनाशी] such as Diuron (1 kg/ha in nursery [नर्सरी]) and Nephromide (2 kg/ha in the main orchard) are used for weed control [खरपतवार नियंत्रण]. Pomegranate [अनार] is prone to several diseases like bacterial blight [झुलसा], anthracnose [फफूंदजनित रोग], fruit rot [फल सड़न], Cercospora leaf spot [सर्कोस्पोरा पत्ती धब्बा], Alternaria fruit spot, and Fusarium wilt [फ्यूजेरियम मुरझान रोग]. Management includes fungicide [फफूंदनाशी] sprays (e.g., Dithane M-45, Captan, Bavistin), sanitation, and orchard hygiene. Pest [कीट] issues include the anar butterfly (fruit borer [फल बेधक कीट]), bark-eating caterpillars, whiteflies, aphids, mealy bugs, and fruit flies. Integrated Pest Management [समेकित कीट प्रबंधन] (IPM) practices include cultural sanitation, pruning [फ枝剪ाई], biological agents like Trichogramma [ट्राइकोग्रामा], neem-based products, polythene bagging, and chemical treatments like malathion. Grape ``` ---- **ICAR Kharif Agro-Advisories for Farmers** ``` Maharashtra The Kharif season, stretching from June to October, is a crucial agricultural period for the state of Maharashtra, significantly influencing the livelihoods of millions of farmers. Characterized by the onset of the southwest monsoon [मानसून], this season supports the cultivation of key crops such as rice [चावल], cotton [कपास], soybeans, pulses, and millets. However, climate [जलवायु] variability, erratic rainfall, and changing weather [मौसम] patterns pose continuous challenges to sustainable agriculturalproduction. Inthelightofthesechallenges, the Kharif 2025 Agro-Advisoryaims to provide timely, region-specific, and science-based recommendations to empower farmerswiththeknowledgeneededtomakeinformeddecisions. REGIONAL ADVISORY Maharashtra is divided into several agroclimatic zones, each with unique characteristics influencing crop selection [फसल चयन], sowing [बुवाई] windows, and input management. The following region-wise advisories aim to support farmers with tailored recommendations for improved productivity and resilience. VIDARBHA REGION The Vidarbha region of Maharashtra is composed of Bhandara, Chandrapur, Gondia Gadchiroli, Nagpur, Amravati, Akola, Yavatmal, Buldhana, Wardha, Washim and possesses state agricultural university viz., Dr. Panjabrao Deshmukh Krishi Vidyapeeth, Akola. Soil Testing [मृदा परीक्षण] & Preparation (All Crops) Soil testing [मृदा परीक्षण] is crucial for effective fertilizer management [उर्वरक प्रबंधन], optimizing input use, and maintaining soil fertility [मृदा उर्वरता]. For proper soil sampling [मृदा नमूना लेना], the recommended depths are 15- 20 cm for crops like sorghum [ज्वार], rice [चावल], groundnut [मूंगफली], and wheat [गेहूं]; 30 cm for cotton [कपास], sugarcane [गन्ना], and banana [केला]; and 30 cm for fruit trees, sampled from a distance of 1-1.5 feet from the trunk. Additionally, applying decomposers to crop [फसल] residues like straw and leaves enhances organic matter content [जैविक पदार्थ की मात्रा], improves soil structure [मृदा संरचना], and boosts water retention [पानी धारण क्षमता], contributing to sustainable agricultural practices [कृषि पद्धतियाँ]. ICAR Kharif Agro-Advisory [कृषि सलाह] 2025 CEREALS CROPS Paddy ``` ---- **ICAR Rabi Agro-Advisories for Farmers 2025** ``` # VIDARBHA Vidarbha, located in eastern Maharashtra, comprises the districts of Nagpur, Amravati, Akola, Yavatmal, Buldhana, Wardha, Chandrapur, Gadchiroli, and Washim. The region receives moderate to high rainfall ranging from 800 to 1200 mm, and has varied soil [मिट्टी] types, including black cotton [कपास] soils and red loamy soils. Major Rabi crops [रबी फसलें] grown in Vidarbha include chickpea [चना], wheat [गेहूं], mustard [सरसों], and orange [संतरा]. # Cereal [अनाज] crops ## Wheat [गेहूं] For Rabi wheat [गेहूं] in Vidarbha, sowing [बुवाई] under irrigated conditions should be completed between 15th and 30th November. Recommended varieties include AKAW-5100, AKW-1071 (Purna), AKW-3722 (Vimal), PDKV Sardar, HD-2189, and HD-2380. Use a seed rate [बीज दर] of 100-125 kg/ha with row spacing [पंक्तियों के बीच दूरी] of 15-22.5 cm. Before sowing [बुवाई], treat seeds with carbendazim (2 g/kg) or thiram (3 g/kg) to prevent bacterial diseases, followed by biofertilizers [जैव उर्वरक] Farmer [किसान] Wheat [गेहूं] plot Var. Phule Samadhan (Azotobacter 250 g + PSB 250 g/10 kg seed [बीज]). Apply a basal dose [प्रारंभिक मात्रा (उर्वरक की)] of NPK fertilizer [उर्वरक] (80-120:40-50:40-50 kg/ha), with 50% nitrogen [नाइट्रोजन] as basal and the remainder split at crown root [मुकुट जड़] initiation 181 ``` ---- **ICAR Rabi Agro-Advisories for Farmers 2025** ``` ### Sesame [तिल] VRI(Sv) 2, TMV 7, VRI 3, and VRI 4. Seed treatment [बीज उपचार] with Trichoderma [ट्राइकोडर्मा] @ 4 g/kg of seed [बीज], Bacillus subtilis @ 2 g/kg seed [बीज], or NSKE 4%. Intercropping [अंतरफसल] of sesamum + redgram (6:1) for additional net returns. Apply 35:23:23 kg N:P₂O₅:K₂O/ha and TNAU micronutrient [सूक्ष्म पोषक तत्व] mixture @ 12.5 kg/ha as enriched FYM. Thinning [间दाई करना] of excess seedlings is to be done to induce basal branching. Application of six packets of azophos (1200 g/ha) ### Sugarcane [गन्ना] COC 671, COC 92061, COC 6304, COC 22, CO 86032, 83 R 23, CO 18009. Other varieties by SBI are Co 11015 (Atulya), Co 14012, and Co 18009. Apply 275:62.5:112.5 kg N:P₂O₅:K₂O/ha. Intercrop with dhaincha/sunnhemp in wider rows and incorporate. Use a power weeder [निराई करने वाली मशीन] for weeding [निराई करना] and earthing up [मिट्टी चढ़ाना] with a ridger to save the cost of cultivation [खेती की लागत]. Trash mulching [मल्चिंग] to avoid the incidence of early shoot borer [शिखर छेदक कीट]. Foliar spray [पत्तियों पर छिड़काव] of Sugarcane [गन्ना] booster. ## Horticultural crops ### Fruit crops #### Banana [केला] ``` ---- **ICAR Rabi Agro-Advisories for Farmers 2025** ``` ICAR Rabi Agro-Advisory [कृषि सलाह] 2025 # Livestock [पशुधन] ## Dairy [दुग्ध व्यवसाय] Cattle Timely vaccination (FMD, HS, BQ) and deworming are essential in the Rabi season, along with protection from mastitis, pneumonia, and lumpy skin disease [रोग] in cold, damp months. They should be fed green fodder [हरा चारा] like berseem and oats, supplemented with dry fodder [सूखा चारा], concentrates, and warm water, while sheds must be kept clean, dry, and windproof with bedding or blankets for calves ## Goat Goats require vaccination (PPR, ET), regular deworming, and monitoring for ectoparasites, scabies, hoof rot, and respiratory issues. Their diet should include 0.5-2 kg green fodder [हरा चारा], 200-400 g concentrate, and tree leaves, with warm water during winter. Housing should be dry, elevated, and windproof to protect kids from the cold. ## Poultry [पोल्ट्री पालन] Poultry [पोल्ट्री पालन] must be vaccinated (Ranikhet, IBD, Fowl Pox) and protected from coccidiosis, avian influenza, and respiratory stress. They need high-energy feed with calcium [कैल्शियम] and vitamins, grit, and electrolytes during cold stress [ठंड के कारण होने वाला तनाव], while coops should be insulated, well-ventilated, dry, and biosecure. Overall, the focus is on disease [रोग] prevention, warmth, energy-rich feeding, and gradual transition to summer care by February-March. # VIDARBHA Vidarbha, located in eastern Maharashtra, comprises the districts of Nagpur, Amravati, Akola, Yavatmal, Buldhana, Wardha, Chandrapur, Gadchiroli, and Washim. The region receives moderate to high rainfall ranging from 800 to 1200 mm, and has varied soil [मिट्टी] types, including black cotton [कपास] soils and red loamy soils. Major Rabi crops [रबी फसलें] grown in Vidarbha include chickpea [चना], wheat [गेहूं], mustard [सरसों], and orange [संतरा]. # Cereal [अनाज] crops ## Wheat [गेहूं] ``` ---- **ICAR Kharif Agro-Advisories for Farmers** ``` 1. Follow crop rotation [फसल चक्र] avoid cotton [कपास] sowing [बुवाई] followed by tomato [टमाटर], chickpea [चना], etc. 2. Sowing [बुवाई] of intercrop or mixed crop [फसल] like maize [मक्का], cowpea [लोबिया], Black gram [उड़द], green gram [मूंग] and use of trap crop [फंदा फसल] like marigold, castor [अरंडी], etc. 3. Sowing [बुवाई] of okra [भिंडी] as a trap crop [फंदा फसल] in cotton [कपास] for the control of Pink Bollworm [गुलाबी सुंडी]. 4. Avoid plant growth promoters and pesticides during first three months and use botanical pesticides or biopesticides [जैव कीटनाशी] 5. Spray of 5 % NSKE at 60 DAS 6. Install 40 pheromone traps [फेरोमोन जाल] per ha for mass trapping [सामूहिक फंदा] of pink bollworm [गुलाबी सुंडी]. Maharashtra PULSE [दाल] CROPS Soybean [सोयाबीन] The own seed [बीज] of Soybean [सोयाबीन] should be used for next Kharif season after testing its germination [अंकुरण] to save money as well as it will help to face the situation of seed [बीज] shortage in the market. Seed germination [बीज अंकुरण] should be tested before sowing [बुवाई] and good quality seed [गुणवत्तापूर्ण बीज] with more than 70 % germination [अंकुरण] should be used for sowing [बुवाई] only. Improved varieties like MAUS-162, MAUS-612, MAUS-725, Phule Durva, Phule Kimaya, PDKV Yellow Gold, PDKV Amba should be used for sowing [बुवाई]. Soybean [सोयाबीन] seed [बीज] should be treated with Thiram @ 3 g/kg or Trichoderma [ट्राइकोडर्मा] @ 4 g/kg of seed [बीज] and inoculated with Rhizobium [राइजोबियम] and PSB @ 100 ml/10 kg of seed [बीज] before sowing [बुवाई]. Sowing [बुवाई] of soybean [सोयाबीन] should be avoided in the fields where soybean [सोयाबीन] seed production [बीज उत्पादन] was taken in the last summer season. Follow IPM package for the control of pests and diseases in soybean [सोयाबीन] as give below: - 1. Sowing [बुवाई] should be completed before 15’n July to avoid pest infestation [कीट प्रकोप]. 2. Seed treatment [बीज उपचार] of Thiram @2-3 g per kg or Trichoderma [ट्राइकोडर्मा] @5 g per kg of seed [बीज]. 3. Seed treatment [बीज उपचार] with Thiamethoxam 30 % @ 10 ml per kg of seed [बीज] for management of stem fly. ``` ---- **ICAR Kharif Agro-Advisories for Farmers** ``` Black gram [उड़द] The recommended seed rate [बीज दर] is 15-20 kg/ha with a spacing [अंतर] of 30×10 cm. Seeds should be treated with Trichoderma [ट्राइकोडर्मा] at 5 g/kg along with Rhizobium [राइजोबियम] and PSB at 25 g/kg each. Apply fertilizers at a rate of 20:40 kg N:P per hectare. Intercropping [अंतरफसल] with pigeon pea [अरहर] and other kharif crops [खरीफ फसलें] is advised for better resource utilization. Irrigation [सिंचाई] should be provided at critical stages such as flowering and pod [फली] filling to ensure healthy growth and yield [उत्पादन]. FRUIT & VEGETABLE CROPS Pomegranate [अनार] (Mrig Bahar) Pomegranate [अनार] cultivation during Mrig Bahar requires pruning [फ枝剪ाई] to remove diseased branches, followed by an application of 1% Bordeaux mix. Pre- flowering fertilization [फलधारण] includes 700 g urea [यूरिया], 1600 g SSP, and 400 g MOP per tree. Dusting with 4% copper [तांबा] dust or bleaching powder helps in disease [रोग] prevention. Regular pest control [कीट नियंत्रण] with Azadirachtin or alternate insecticides [कीटनाशक] every 15 days is crucial. At the fruiting stage, apply 500 g DAP + 100 g MOP per tree at the lemon [नींबू] size stage, and 200 g 19:19:19 + 100 g MOP at the guava [अमरूद] size stage. Maharashtra Grape After pruning [फ枝剪ाई], grapevines are treated with Hydrogen Cyanamide (30-40 ml/L) on the top 2-3 buds to encourage growth. GA sprays of 10 ppm are applied 17-18 days after pruning [फ枝剪ाई], followed by 15 ppm after 4-5 days. Mealybug [मैलिबग] control in September involves removing bark and spraying [छिड़काव] Methomyl 40 SP at 1 g/L Banana [केला] ``` ---- **ICAR Rabi Agro-Advisories for Farmers 2025** ``` For successful chickpea [चना] cultivation, farmers are advised to use high-yielding desi varieties like RVG-202, RVG-204, JG-16, JG-130, and JG-24, and for Kabuli types, varieties such as JGK-1, JGK-2, JGK-3, KAK-2, Shubhra, and Ujjwal are recommended. Sowing [बुवाई] should ideally be done between mid-October and mid-November using the ridge and furrow [मेढ़ और नाली] or raised bed [ऊँचा क्यारी] method to optimize water and seed [बीज] usage. Intercropping [अंतरफसल] with coriander [धनिया] or mustard [सरसों] with 8:2 ratios enhances resource use efficiency. The ideal spacing [अंतर] is 30×10 cm with a seed rate [बीज दर] of 75-80 kg/ha, increase the seed rate [बीज दर] by 25 kg/ha if sowing [बुवाई] is delayed beyond November 30. Before sowing [बुवाई], apply Trichoderma [ट्राइकोडर्मा] culture @ 5 kg/ha mixed with vermicompost [केंचुआ खाद] for wilt disease [मुरझाने की बीमारी] prevention. For seed treatment [बीज उपचार], use a combination of thiophanate-methyl + pyraclostrobin (2 ml), boron [बोरॉन] (1 g), molybdenum [मोलिब्डेनम] (1 g), Rhizobium [राइजोबियम] (8 g), and PSB culture (10 g)/kg of seed [बीज]. Alternatively, organic seed treatment [जैविक बीज उपचार] can be done with 5 g each of Trichoderma [ट्राइकोडर्मा], Rhizobium [राइजोबियम], and PSB @ 10 g/kg seed [बीज]. Nutrient application should include 15-20 kg N, 40 kg P₂O₅, 20 kg sulfur, 5 t of FYM, and 1 kg ammonium molybdate/ha. Though chickpea [चना] is largely a rainfed crop [फसल], irrigation [सिंचाई] at the branching stage and at pod [फली] formation significantly enhances yield [उत्पादन]. For weed management [खरपतवार प्रबंधन], apply pendimethalin (30% EC) @ 0.7-1.0 kg a.i. /ha within 48 hours of sowing [बुवाई], and follow up with one hand weeding [निराई] if needed. For pod borer [फली छेदक इल्ली] control, install 50 bird perches and 10 pheromone traps [फेरोमोन जाल] per hectare ``` ---- **ICAR Kharif Agro-Advisories for Farmers** ``` Banana [केला] In Kerala, banana [केला] cultivation during the Kharif season (June to September) begins with land preparation [भूमि तैयार करना] in May or early June. The land is ploughed or dug 2-3 times to loosen the soil [मिट्टी], and pits of size 60 x 60 x 60 cm or 45 x 45 x 45 cm are prepared. These pits are filled with topsoil mixed with 10-15 kg of farmyard manure [गोबर खाद] (FYM), 1 kg of neem cake [नीम खली], and wood ash or sand to improve soil fertility [मृदा उर्वरता] and drainage. Planting is typically done in June or July, using either healthy sword suckers or tissue-cultured plants. Common varieties cultivated during this season include Nendran, Robusta, Poovan, Grand Naine (G-9), and Red Banana [केला]. The spacing [अंतर] varies depending on the variety, with tall varieties planted at 2.5 x 2.5 m and dwarf or high-density types at 1.5 x 1.5 m or 1.8 x 1.8 m. Proper drainage is essential during the monsoon [मानसून] to prevent rhizome rot [राइजोम सड़न (तना सड़ना)]. Nutrient management [पोषक तत्व प्रबंधन] involves applying FYM at 10-20 kg per pit as a basal dose [प्रारंभिक मात्रा (उर्वरक की)]. Chemical fertilizers [रासायनिक उर्वरक] like nitrogen [नाइट्रोजन] (200 g), phosphorus [फॉस्फोरस] (60 g), and potassium [पोटाश] (200 g) per plant are applied in 3-4 splits at 1, 3, 5, and 7 months after planting. Foliar sprays of micronutrients [सूक्ष्म पोषक तत्व] such as zinc [जिंक], magnesium, and boron [बोरॉन] are also recommended. 122 Kerala Weed control [खरपतवार नियंत्रण] is achieved by mulching [मल्चिंग] with banana [केला] leaves or straw, which also helps in moisture conservation [नमी संरक्षण]. Intercropping [अंतरफसल] with legumes like cowpea [लोबिया] or groundnut [मूंगफली] is sometimes practiced. Drainage channels are constructed to avoid water stagnation [पानी का जमाव] during heavy rains. ``` ---- **ICAR Rabi Agro-Advisories for Farmers 2025** ``` ICAR Rabi Agro-Advisory [कृषि सलाह] 2025 aquaculture [जलीय कृषि], particularly shrimp farming [कृषि करना], also plays a significant role in supporting coastal livelihoods. Sustainable fishing practices such as avoiding juvenile catch, observing closed seasons, and using recommended mesh sizes are essential to conserve marine resources [समुद्री संसाधन]. Farmers engaged in aquaculture [जलीय कृषि] should adopt proper pond preparation, seed [बीज] stocking at optimal densities, regular water quality monitoring, and balanced feeding to maximize yield [उत्पादन] and profitability. Strengthening fish value chains through hygienic handling, cold storage [शीतगृह], and cooperative marketing can further enhance income opportunities for coastal communities. # WESTERN MAHARASHTRA (DESH REGION) &amp; KHANDESH REGION The Western Maharashtra (Desh region), comprising Pune, Satara, Sangli, Kolhapur, and Solapur districts &amp; Khandesh region, comprising Nashik, Dhule, Ahmednagar, Jalgaon &amp; Nandurbar Districts, Western Maharashtra receives moderate rainfall ranging from 500-900 mm annually. The soils here are predominantly black to medium black and well-drained, making them suitable for both field [खेत] and horticultural crops. Major crops grown in this region include cereals like sorghum [ज्वार] and wheat [गेहूं]; pulses such as chickpea [चना] and oilseeds like safflower [कुसुम] and linseed [अलसी]. Sugarcane [गन्ना] is an important commercial crop [फसल] widely cultivated in this zone. The region also excels in horticulture [उद्यानविद्या], producing high-value fruit crops such as pomegranate [अनार], banana [केला], and grapes [अंगूर], along with vegetables like onion [प्याज], tomato [टमाटर], and brinjal [बैंगन]. ## Cereal [अनाज] crops ### Sorghum [ज्वार] ``` [tool:search_terms] Matching Terms for `మధ్యపంటలు` Strip intercropping -> पट्टी पद्धति की अंतरफसल खेती (patti paddhati ki antarfasal kheti) [72%] Intervening crop -> मध्यवर्ती फसल (madhyavarti fasal) [70%] [tool:search_terms] Matching Terms for `కాలీఫ్లవర్` Cauliflower -> फूलगोभी (phoolgobhi) [90%] | M9: 1 | N9: 0 | O9: didn't provide required guidance for intercrop planning. And missed translation | P9: Completed | Q9: 1 | R9: Reject | S9: In QID 5-1, the response fails to provide required intercropping guidance for cauliflower in Buldhana, creating a major Accuracy/Completeness drop (4→1) between stages. The evaluator overlooked missing key information and failed to penalize Citation Accuracy and Translation Accuracy. This fundamental evaluation collapse requires a Score of 1 (Reject). Reject the review and perform a full re-evaluation across all affected rubric dimensions. | T9: updated
A10: 6 | B10: 6-1 | C10: బెంగళూరు మార్కెట్‌లో ఆపplesల ప్రస్తుత మార్కెట్ ధరలు ఏమిటి? | D10: బెంగళూరు మార్కెట్‌లో ఆపిల్ ధరలు ఈ విధంగా ఉన్నాయి: * **బెంగళూరు ఏ.పి.ఎం.సి — యార్డ్ ౧:** మోడల్ ధర ₹౭౫౫౫ ప్రతి క్వింటల్ (కనిష్ట: ₹౭౧౮౦, గరిష్ట: ₹౭౯౩౦). * **బెంగళూరు హోల్‌సేల్ హబ్:** మోడల్ ధర ₹౭౩౨౮ ప్రతి క్వింటల్ (కనిష్ట: ₹౬౮౨౧, గరిష్ట: ₹౭౮౫౦). ఈ ధరలు ౧౦ గంటల క్రితం నమోదయ్యాయి. **మూలం: మండి ధరలు** మీకు వేరే ఏదైనా పంట ధరల గురించి తెలుసుకోవాలా? | E10: 4 | F10: 1 | G10: 1 | H10: 1 | I10: 4 | J10: 3 | K10: 3 | L10: [tool:get_mandi_prices] **Mandi Price Discovery** [Today's Date: Monday, 25 May 2026] Commodity: Apple Market: Bangalore APMC — Yard 1 (mock), Bengaluru Urban, Karnataka Price: Rs./Quintal 7555 (Min: 7180, Max: 7930) 10 hours ago --- Commodity: Apple Market: Bangalore wholesale hub (mock), Bengaluru Urban, Karnataka Price: Rs./Quintal 7328 (Min: 6821, Max: 7850) 10 hours ago [tool:search_commodity] ### Commodity matches for `apples` | Commodity | Matched Term (Score) | Code | |---|---|---| | **Apple** | apple (92%) | `17` | | **Grapes** | grapes (80%) | `22` | | **Pineapple** | pineapple (76%) | `21` | | **Wood Apple** | wood apple (73%) | `428` | | **Water Apple** | water apple (70%) | `425` | [tool:forward_geocode] Bengaluru, Bangalore North, Karnataka, India (Latitude: 12.977, Longitude: 77.59) | M10: 0 | N10: 1 | O10: Number are and names are not translated completly, and incompleteness in response | P10: Completed | Q10: 1 | R10: Reject | S10: In QID 6-1, the response misinterprets 'apples' transliteration ('ఆపplesల') and leaves numerical market prices unformatted for low-literacy users. Stage 2 correctly flagged severe translation and formatting flaws affecting Accuracy/Completeness (4→3) and Translation Accuracy (4→2). This major multi-rubric evaluation conflict warrants a Score of 1 (Reject). Reject the review and re-evaluate all linguistic and accuracy rubrics. | T10: updated
A11: 7 | B11: 7-1 | C11: సాంగ్లీలో అల్లం పంటకు విత్తన పరిమాణం ఎంత? | D11: సాంగ్లీలో అల్లం పంటకు హెక్టారుకు ౧౮౦౦ నుండి ౨౦౦౦ కి.గ్రా విత్తన పరిమాణం అవసరమవుతుంది. మీరు సుప్రభ, సురుచి మరియు సురవి వంటి సరైన రకాలను ఎంచుకోవాలని సిఫార్సు చేయబడింది. **మూలం: ఐ.సి.ఎ.ఆర్. ఖరీఫ్ అగ్రో-అడ్వైజరీస్** అల్లం విత్తన శుద్ధి మరియు నాటడం గురించి మీకు మరిన్ని వివరాలు కావాలా? | E11: 3 | F11: 1 | G11: 1 | H11: 1 | I11: 2 | J11: 3 | K11: 3 | L11: [tool:search_documents] > Search Results for `seed rate for ginger crop in Sangli Maharashtra` **ICAR Kharif Agro-Advisories for Farmers** ``` 0.5 ml/L water for three hours before transplanting [पुनः रोपाई] may be followed for better control. Fruit fly [फलों की मक्खी] in cucurbits causes great losses which can be managed by use of food bait @100 ml/bait prepared by mixture of 1 kg cucumber [खीरा] fruit pulp + 50 g gur + 100 ml cow urine + 0.5 L water, diluted in 5 L water and added with 10 ml malathion along with installation of Pheromone trap [फेरोमोन जाल] with Cuelure @ 20 nos/ ha. Sucking insect [कीट] pest [कीट] are seen in many vegetable crops for which spraying [छिड़काव] of Thiamethoxam 25% WG @ 80 g or Acetamiprid 20 SP @ 125 ml/ha will keep the population under control. During rainy season, wilting is observed in solanaceous crops which can be controlled by spraying [छिड़काव] and soil drenching [मिट्टी में घोल डालना] with 3 g Copper [तांबा] oxycloride+1 g Plantomycin per litre of water. SPICE CROPS Turmeric [हल्दी] Suitable varieties are Roma, Rashmi, Lakadong, Rajendra Sonia. Treat the rhizome [कंद] with Trichoderma [ट्राइकोडर्मा] viridae @ 10 g/kg of seed [बीज] to save the crop [फसल] from diseases. Apply bio-consortia (Azotobacter, Azospirillum & PSB) @ 12 kg/ha mixed with FYM at the time of planting for improving germination [अंकुरण] and productivity. Ginger [अदरक] Cultivate suitable ginger [अदरक] varieties- Suprabha, Suruchi and Suravi with seed rate [बीज दर] of 1800-2000 kg/ha. Select high loamy land for cultivation. Raised bed [ऊँचा क्यारी] of size 1 m width, 15 cm height and of convenient length may be adopted along with making channels for draining excess rain water. Before sowing [बुवाई] dip rhizomes in a slurry [द्रव और उसमें निलंबित ठोस पदार्थों का मिश्रण] of 1 g Carbendazim, 3 g Mancozeb and 1 g Plantomycin for half an hour and dry in the shade. Banana [केला] ``` ---- **ICAR Rabi Agro-Advisories for Farmers 2025** ``` ICAR Rabi Agro-Advisory [कृषि सलाह] 2025 aquaculture [जलीय कृषि], particularly shrimp farming [कृषि करना], also plays a significant role in supporting coastal livelihoods. Sustainable fishing practices such as avoiding juvenile catch, observing closed seasons, and using recommended mesh sizes are essential to conserve marine resources [समुद्री संसाधन]. Farmers engaged in aquaculture [जलीय कृषि] should adopt proper pond preparation, seed [बीज] stocking at optimal densities, regular water quality monitoring, and balanced feeding to maximize yield [उत्पादन] and profitability. Strengthening fish value chains through hygienic handling, cold storage [शीतगृह], and cooperative marketing can further enhance income opportunities for coastal communities. # WESTERN MAHARASHTRA (DESH REGION) &amp; KHANDESH REGION The Western Maharashtra (Desh region), comprising Pune, Satara, Sangli, Kolhapur, and Solapur districts &amp; Khandesh region, comprising Nashik, Dhule, Ahmednagar, Jalgaon &amp; Nandurbar Districts, Western Maharashtra receives moderate rainfall ranging from 500-900 mm annually. The soils here are predominantly black to medium black and well-drained, making them suitable for both field [खेत] and horticultural crops. Major crops grown in this region include cereals like sorghum [ज्वार] and wheat [गेहूं]; pulses such as chickpea [चना] and oilseeds like safflower [कुसुम] and linseed [अलसी]. Sugarcane [गन्ना] is an important commercial crop [फसल] widely cultivated in this zone. The region also excels in horticulture [उद्यानविद्या], producing high-value fruit crops such as pomegranate [अनार], banana [केला], and grapes [अंगूर], along with vegetables like onion [प्याज], tomato [टमाटर], and brinjal [बैंगन]. ## Cereal [अनाज] crops ### Sorghum [ज्वार] ``` ---- **ICAR Kharif Agro-Advisories for Farmers** ``` 163 ICAR Kharif Agro-Advisory [कृषि सलाह] 2025 60 kg N, 30 kg P₂O₅, and 30 kg K₂O per hectare for optimal crop nutrition [फसल पोषण]. Millets can be intercropped with soybean [सोयाबीन]. Conduct three hoeings with a hand hoe [खुरपी] during early growth stages for eﬀective weed suppression. Spray Mancozeb (0.2%) at early crop [फसल] stages if Blast [झुलसा], Brown Spot, or Rust [गेरू रोग] symptoms appear. Rogue out diseased plants to manage spread and for armyworms, cutworms, and leaf-scraping beetles, apply Thiamethoxam @ 5 g/15 litres of water for eﬀective protection. PULSE [दाल] CROPS Blackgram Conduct deep summer ploughing [जुताई] to expose and destroy the eggs, larvae, and pupae of major pests like pod borer [फली छेदक इल्ली], c a t e r p i l l a r s , a n d w e e v i l s . M i x FYM/compost [कम्पोस्ट] into the soil [मिट्टी] 10-15 days before sowing [बुवाई]. Ensure the field [खेत] is free from weeds [खरपतवार] for optimal crop [फसल] growth. Use high-yielding varieties like PU 31 and LBG-20 (Teja). PU 31 is tolerant to Yellow Mosaic Virus [पीला मोज़ेक विषाणु रोग] (YMV) and well- suited for Kharif cultivation, while LBG- Varietal demonstration in blackgram 20 performs well in all seasons. Use a seed rate [बीज दर] of 10-15 kg/ha (or 2.5-3.75 kg/sangam). Sowing [बुवाई] can be done by broadcasting or dibbling [छिद्र बोवाई विधि] at a spacing [अंतर] of 15 cm ``` ---- **ICAR Kharif Agro-Advisories for Farmers** ``` For weed management [खरपतवार प्रबंधन], Pendimethalin is applied pre-emergence [अंकुरण] and Imazethapyr post-emergence [अंकुरण], along with hand weeding [निराई] at 20 and 40 days after sowing [बुवाई] (DAS). To manage sucking pests, seed treatment [बीज उपचार] with Imidacloprid is eﬀective, while collar rot [मूल तना सड़न] can be controlled by treating seeds with Fluxapyroxad or a combination of Carboxin and Thiram. In case of defoliator infestation, spraying [छिड़काव] Indoxacarb, Lambda- cyhalothrin, or a Novaluron mixture is recommended. For rust [गेरू रोग] and leaf spot [पत्तियों पर धब्बे] diseases, fungicides [फफूंदनाशी दवाएँ] like Hexaconazole or Pyraclostrobin should be applied. Additionally, 75% of the recommended dose of fertilizers (RDF) should be supplemented with 25 kg/ha of Mycorrhiza [मायकोराइजा] and Rhizobium [राइजोबियम] seed treatment [बीज उपचार] to enhance soil health [मृदा स्वास्थ्य] and crop productivity [फसल उत्पादकता]. Cotton [कपास] (Bt & Desi) Cotton [कपास] cultivation thrives best in well-drained loamy to sandy loam soils. Prior to sowing [बुवाई], deep ploughing [गहरी जुताई] is essential along with the incorporation of 10-15 t/ha of farmyard manure [गोबर खाद] (FYM) to enhance soil fertility [मृदा उर्वरता]. Sowing [बुवाई] is typically carried out in June- July under rainfed conditions and during April-May for irrigated crops. Recommended spacing [अंतर] for normal planting is 90-120 × 30-45 cm, while under high-density planting [उच्च घनता रोपण] (HDP) systems, 60 × 30 cm spacing [अंतर] is advised. Suitable varieties include Bt hybrids like G. Cot. Hy. 24 and 26, and desi types such as GADC-3 and GADC-4. The seed rate [बीज दर] varies by type, with 1.5-2 kg/ha for Bt varieties and 10-12 kg/ha for desi types. Gujarat ``` ---- **ICAR Kharif Agro-Advisories for Farmers** ``` Buffalo Allow buffalo for wallowing in water as they have fewer sweet glands compared to cattle to maintain their body's thermo-equilibrium. Water-soaked gunny bag or other cloth should kept on a body to avoid occurrence of heat stroke. Goat Animals should be vaccinated before monsoon [मानसून] season for Enterotoxaemia and Peste des petes (PPR) ruminants' diseases to avoid great losses. Improved breeds like Osmanabadi should be used for higher income. Regular deworming should be done after every month to goat kids for six months for good health and weight gain. Poultry [पोल्ट्री पालन] In the summer the poultry [पोल्ट्री पालन] shed should be kept cool. Plants more trees around the shed. The roof of the shed should be covered with grass, so that the temperature [तापमान] remains under control. Exhaust fan should be kept in the shed, so that the hot air inside shed is thrown out. Use foggers, so the shade will cool down. Improved backyard poultry [पोल्ट्री पालन] breeds like Grampriya, Shrinidhi, Kaveri, Giriraja and Vanaraja should be used to boost up the income of small and marginal farmers. WESTERN MAHARASHTRA Western Maharashtra is comprised of Ahmednagar, Pune, Satara, Sangli, Kolhapur, Solapur. The region has moderate rainfall and Black to medium black, well-drained soils. This region has state agricultural university viz., Mahatma Phule Krishi Vidyapeeth, Rahuri, Ahmednagar. CEREAL [अनाज] CROPS Rice [चावल] In Western Maharashtra, nursery [नर्सरी] sowing [बुवाई] for Kharif rice [चावल] generally begins in late May to mid-June, aligning with the onset of monsoon [मानसून]. Recommended varieties include Phule Radha, Indrayani, Sahyadri, and Kolhapur-1, chosen for local adaptability and consumer preference. About 40-50 kg of seed [बीज] per hectare of main field [खेत] is required for a nursery [नर्सरी] area of 800-1000 m². Seeds are soaked in water for 24 hours, then incubated for another 24-36 hours to promote uniform germination [अंकुरण]. Treat seeds Maharashtra ``` ---- **ICAR Kharif Agro-Advisories for Farmers** ``` SPICE CROPS Ginger [अदरक] and Turmeric [हल्दी] Farmers are advised to complete the sowing [बुवाई] of ginger [अदरक] (variety Nadia) and turmeric [हल्दी] (varieties Megha Turmeric [हल्दी] 1 or Lakadong) without delay. Use a seed rate [बीज दर] of 15-20 169 ICAR Kharif Agro-Advisory [कृषि सलाह] 2025 quintals per hectare and maintain a spacing [अंतर] of 30 cm × 30 cm. Before sowing [बुवाई], treat rhizome [कंद] seeds by dipping them in a solution of Trichoderma [ट्राइकोडर्मा] viride @ 4 g/litre of water for 5 minutes or Trichoderma [ट्राइकोडर्मा] harzianum @ 10 ml/litre to prevent rhizome rot [राइजोम सड़न (तना सड़ना)]. For already sown crops, carry out proper weeding [निराई करना] and earthing up [मिट्टी चढ़ाना] to promote healthy growth. Ensure planting in ridges and furrows with good drainage. Farmers may also opt for intercropping [अंतरफसल] with crops like soybean [सोयाबीन], rice [चावल] bean, French bean, finger millet [रागी], or maize [मक्का] for better resource use and income diversification. To conserve soil moisture [मिट्टी की नमी] and control weeds [खरपतवार], mulch the beds using dry paddy straw or green leaves. For eﬀective disease management [रोग प्रबंधन], especially soft rot, spray Trichoderma [ट्राइकोडर्मा] viride or Trichoderma [ट्राइकोडर्मा] harzianum @ 10 ml/litre or neem oil [नीम का तेल] (10,000 ppm) @ 2 ml/litre as a preventive measure. LIVESTOCK [पशुधन] Piggery ``` ---- **ICAR Rabi Agro-Advisories for Farmers 2025** ``` . Pusa 209, GNG 1969, KAK-2, Shubhra, Ujjaval, and Pusa 256 are the Kabuli type varieties. For late sowing [बुवाई]: GNG 2144 (Teej) and GNG 1488 (Sangam) are Kabuli-type varieties. Desi varieties require 70-80 kg/ha and Kabuli 80-90 kg/ha for sowing [बुवाई]. For late sowing [बुवाई], use 90-100?kg/ha, and for utera cropping, 100-120 kg/ha. Small-seeded variety 50-60 kg, medium 60-70 kg, Kabuli/bold-seeded 80-90 kg, and extra bold-seeded 100-110 kg seed [बीज] should be used. Apply 8-10 t/ha well-decomposed FYM every three years to enhance soil fertility [मृदा उर्वरता]. ``` ---- **ICAR Kharif Agro-Advisories for Farmers** ``` KHANDESH/ NORTHERN MAHARASHTRA This region of Maharashtra is comprised of Jalgaon, Dhule, Nandurbar, Nashik). Rainfall of the region is 600-900 mm and it has Medium to deep black soils. This region has state agricultural university viz., Mahatma Phule Krishi Vidyapeeth, Rahuri, Ahmednagar (M.S) COMMERCIAL CROPS Cotton [कपास] Use medium to deep black cotton [कपास] soils with good drainage for optimal crop [फसल] performance. Prepare land with 1-2 deep ploughings followed by harrowing [सुरकी चलाना]; adopt ridge [मेड़]-furrow [मेड़] or broad bed-furrow [मेड़] method. Treat seeds with Trichoderma [ट्राइकोडर्मा] viride or Carbendazim for fungal diseases and imidacloprid for sucking pest [रस चूसने वाले कीट] protection. Sow Bt cotton [बीटी कपास] hybrids like RCH-2 BG II or NCS-855 BG II from mid-June to early July, depending on monsoon [मानसून] onset. Maintain spacing [अंतर] of 120 × 60 cm for hybrids and 90 × 45 cm for varieties; use seed rate [बीज दर] of 450-500 g/acre. Apply basal dose [प्रारंभिक मात्रा (उर्वरक की)] of NPK @ 50:25:25 kg/ha based on soil test [मृदा परीक्षण]; supplement with FYM @ 5-10 t/ha. Apply zinc sulphate [जिंक सल्फेट] @ 25 kg/ha in zinc [जिंक]-deficient soils. Ensure field [खेत] has proper drainage to prevent waterlogging [पानी भराव], especially during early growth stages. Provide protective irrigation [संरक्षण सिंचाई] during long dry spells, particularly during flowering and boll development. Apply Pendimethalin @ 1.0 kg a.i./ha as pre-emergence herbicide [अंकुरण पूर्व खरपतवारनाशी]; ICAR Kharif Agro-Advisory [कृषि सलाह] 2025 follow with hand weeding [निराई] at 20-25 DAS. Monitor for sucking pests (jassids, aphids, whiteflies); control using imidacloprid 0.3 ml/l or thiamethoxam 0.25 g/l. ``` ---- **ICAR Kharif Agro-Advisories for Farmers** ``` Ginger [अदरक] Cultivate suitable ginger [अदरक] varieties- Suprabha, Suruchi and Suravi with seed rate [बीज दर] of 1800-2000 kg/ha. Select high loamy land for cultivation. Raised bed [ऊँचा क्यारी] of size 1 m width, 15 cm height and of convenient length may be adopted along with making channels for draining excess rain water. Before sowing [बुवाई] dip rhizomes in a slurry [द्रव और उसमें निलंबित ठोस पदार्थों का मिश्रण] of 1 g Carbendazim, 3 g Mancozeb and 1 g Plantomycin for half an hour and dry in the shade. Banana [केला] Banana [केला] crop [फसल] should be planted during June with receipt of rain. Tissue culture [ऊतक संवर्धन] plants and high- density planting may be followed for banana [केला] cultivation for higher productivity. In bearing plants of coconut [नारियल], make circular pit of 30 cm deep 3 ft away from the trunk, apply 60 kg compost [कम्पोस्ट], 500 g urea [यूरिया], 1 kg SSP/300 g of DAP, 1 kg MOP and 200 g borax [बोरैक्स] per bearing plant in the pit and cover with soil [मिट्टी]. LIVESTOCK [पशुधन] Don't allow domestic animals to graze outside during 11 PM to 3 PM as ambient temperature [तापमान] remains high this time. Provide sufficient clean drinking water to cattle and keep their sheds clean. Provide vaccination at regular interval. Cultivate and 189 ICAR Kharif Agro-Advisory [कृषि सलाह] 2025 supplement azolla @ 1-1.5 kg in daily ration of cattle to reduce the feed cost by 20%. Provide supplementary feeding such as broken rice [चावल], paddy, cooked rice [चावल], azolla etc. to the backyard poultry [पोल्ट्री पालन] birds during continuous rain. It is preferable to expose the feed ingredient sacks/bags under sun every week to prevent the feeds getting more moisture. Wash the cattle shed with phenyl (dilution 1:20 ratio with water) and sprinkle bleaching powder around the shed at weekly intervals. Mastitis is a common problem in high yielding cows in rainy season. Keep the cattle shed clean and dry. Clean the udder in soap water daily before milking. Apply Mastilep® ointment over the udder after each milking. ``` ---- **ICAR Kharif Agro-Advisories for Farmers** ``` VEGETABLE CROPS Farmers are advised to prepare the vegetable nursery [नर्सरी] for crops such as cucumber [खीरा], bitter gourd [करेला], ridge gourd [तोरी], bottle gourd [लौकी], chilli [मिर्च], brinjal [बैंगन], and okra [भिंडी] on raised bamboo structures, covering them with polythene to protect seedlings from heavy rain and hailstorms. Planting should be done in ridges and furrows with proper drainage channels to prevent waterlogging [पानी भराव]. It is essential to add farmyard manure [गोबर खाद] (FYM) or vermi- In-situ moisture conservation [स्थल पर नमी संरक्षण] in cabbage [पत्ता गोभी] compost [कम्पोस्ट] in the nursery [नर्सरी] for healthy seedling growth [पौधों की वृद्धि]. To conserve soil moisture [मिट्टी की नमी], prevent soil erosion [मिट्टी का कटाव], and control weeds [खरपतवार], mulching [मल्चिंग] with locally available materials like paddy straw is recommended. Farmers can also make their own compost [कम्पोस्ट] using the 18-day compost [कम्पोस्ट] method, pit method [सिचाई], or by producing vermicompost [केंचुआ खाद] to meet their manure [खाद] requirements. For pest management [कीट प्रबंधन], it is advised to make biopesticides [जैव कीटनाशी] using locally available materials such as leaves, garlic [लहसुन], and tobacco [तंबाकू]. For crops under protected cultivation, including high-value crops, frequent irrigation [सिंचाई] should be provided at 10-15 day intervals, based on the weather [मौसम] conditions. SPICE CROPS Ginger [अदरक] and Turmeric [हल्दी] Farmers are advised to complete the sowing [बुवाई] of ginger [अदरक] (variety Nadia) and turmeric [हल्दी] (varieties Megha Turmeric [हल्दी] 1 or Lakadong) without delay. Use a seed rate [बीज दर] of 15-20 169 ICAR Kharif Agro-Advisory [कृषि सलाह] 2025 ``` [tool:search_terms] Matching Terms for `అల్లం` Ginger -> अदरक (adrak) [80%] Ginger Shoot -> अदरक की कोंप (adrak ki komp) [71%] | M11: 1 | N11: 1 | O11: Number are and names are not translated completly, and incompleteness in response | P11: Completed | Q11: 2 | R11: Needs Re-evaluation | S11: In QID 7-1, regarding ginger seed quantity in Sangli, the response provides raw numerical values without necessary explanatory context or proper Telugu numeral translation. Stage 2 flagged the unreadable number formatting, leading to a Citation Accuracy flip (1→0). This scoring conflict necessitates a Score of 2 (Needs Re-evaluation). Re-evaluate Citation Accuracy and Translation Accuracy. | T11: updated
A12: 8 | B12: 8-1 | C12: కొచ్చి మార్కెట్‌లో ఆపిల్స్ ప్రస్తుత మార్కెట్ ధర ఎంత? | D12: కొచ్చి మార్కెట్‌లో ఆపిల్స్ ధరలు ఈ విధంగా ఉన్నాయి: * **కొచ్చి ఏ.పి.ఎం.సి (యార్డ్ ౧):** మోడల్ ధర ₹౫౦౩౬ ప్రతి క్వింటల్ (కనిష్ట: ₹౪౭౮౦, గరిష్ట: ₹౫౨౯౨). * **కొచ్చి హోల్ సేల్ హబ్:** మోడల్ ధర ₹౪౮౮౪ ప్రతి క్వింటల్ (కనిష్ట: ₹౪౫౪౧, గరిష్ట: ₹౫౨౩౯). ఈ ధరలు ౧౦ గంటల క్రితం నమోదయ్యాయి. **మూలం: మండి ధరలు** మీకు వేరే పంట ధరల గురించి సమాచారం కావాలా? | E12: 3 | F12: 1 | G12: 1 | H12: 1 | I12: 3 | J12: 3 | K12: 3 | L12: [tool:get_mandi_prices] **Mandi Price Discovery** [Today's Date: Monday, 25 May 2026] Commodity: Apple Market: Kochi APMC — Yard 1 (mock), Ernakulam, Kerala Price: Rs./Quintal 5036 (Min: 4780, Max: 5292) 10 hours ago --- Commodity: Apple Market: Kochi wholesale hub (mock), Ernakulam, Kerala Price: Rs./Quintal 4884 (Min: 4541, Max: 5239) 10 hours ago [tool:search_commodity] ### Commodity matches for `Apple` | Commodity | Matched Term (Score) | Code | |---|---|---| | **Apple** | apple (100%) | `17` | | **Pineapple** | pineapple (78%) | `21` | | **Coffee** | kappi (75%) | `41` | | **Ox** | kaale (75%) | `172` | | **Wood Apple** | wood apple (75%) | `428` | [tool:forward_geocode] Kochi, Kerala, India (Latitude: 9.968, Longitude: 76.244) | M12: 0 | N12: 1 | O12: Number are and names are not translated completly, and incompleteness in response | P12: Completed | Q12: 1 | R12: Reject | S12: In QID 8-1, the model response introduces an extra ungrounded market ('Kochi APMC Yard 1') and leaves numbers untranslated. Stage 2 correctly identified the untranslated numerals and hallucinated market, creating a severe scoring contradiction across stages. A Score of 1 (Reject) is necessary due to this unaddressed hallucination. Reject the review and re-evaluate No Fabrication and Citation Accuracy. | T12: updated
